Workbook

Sheet Dim_Riders
A1: Rider_ID | B1: Rider_Name | C1: City | D1: Postcode | E1: Rider_Account_Type | F1: Join_Date | G1: Rider_Risk_Score | H1: Risk_Bucket
A2: ="R-" & (1000 + ROW(A1)) -> R-1001 | B2: ="Rider " & MID(A2,3,4) -> Rider 1001 | C2: =CHOOSE( RANDBETWEEN(1,6), "London", "Manchester", "Birmingham", "Leeds", "Bristol", "Liverpool" ) -> Leeds | D2: =IF(C2="London","E1 " & RANDBETWEEN(1,9) & "AA", IF(C2="Manchester","M" & RANDBETWEEN(1,9) & " 1AA", IF(C2="Birmingham","B" & RANDBETWEEN(1,9) & " 2BB", IF(C2="Leeds","LS" & RANDBETWEEN(1,9) & " 3CC", IF(C2="Bristol","BS" & RANDBETWEEN(1,9) & " 4DD", "L" & RANDBETWEEN(1,9) & " 5EE"))))) -> LS6 3CC | E2: =IF(RAND()>0.8,"Substitute","Account Holder") -> Account Holder | F2: =DATE(RANDBETWEEN(2019,2024),RANDBETWEEN(1,12),RANDBETWEEN(1,28)) -> 44167 | G2: =RANDBETWEEN(40,99) -> 45 | H2: =IF(G2>=80,"High", IF(G2>=60,"Medium","Low")) -> Low
A3: ="R-" & (1000 + ROW(A2)) -> R-1002 | B3: ="Rider " & MID(A3,3,4) -> Rider 1002 | C3: =CHOOSE( RANDBETWEEN(1,6), "London", "Manchester", "Birmingham", "Leeds", "Bristol", "Liverpool" ) -> Manchester | D3: =IF(C3="London","E1 " & RANDBETWEEN(1,9) & "AA", IF(C3="Manchester","M" & RANDBETWEEN(1,9) & " 1AA", IF(C3="Birmingham","B" & RANDBETWEEN(1,9) & " 2BB", IF(C3="Leeds","LS" & RANDBETWEEN(1,9) & " 3CC", IF(C3="Bristol","BS" & RANDBETWEEN(1,9) & " 4DD", "L" & RANDBETWEEN(1,9) & " 5EE"))))) -> M8 1AA | E3: =IF(RAND()>0.8,"Substitute","Account Holder") -> Account Holder | F3: =DATE(RANDBETWEEN(2019,2024),RANDBETWEEN(1,12),RANDBETWEEN(1,28)) -> 44919 | G3: =RANDBETWEEN(40,99) -> 77 | H3: =IF(G3>=80,"High", IF(G3>=60,"Medium","Low")) -> Medium
A4: ="R-" & (1000 + ROW(A3)) -> R-1003 | B4: ="Rider " & MID(A4,3,4) -> Rider 1003 | C4: =CHOOSE( RANDBETWEEN(1,6), "London", "Manchester", "Birmingham", "Leeds", "Bristol", "Liverpool" ) -> Bristol | D4: =IF(C4="London","E1 " & RANDBETWEEN(1,9) & "AA", IF(C4="Manchester","M" & RANDBETWEEN(1,9) & " 1AA", IF(C4="Birmingham","B" & RANDBETWEEN(1,9) & " 2BB", IF(C4="Leeds","LS" & RANDBETWEEN(1,9) & " 3CC", IF(C4="Bristol","BS" & RANDBETWEEN(1,9) & " 4DD", "L" & RANDBETWEEN(1,9) & " 5EE"))))) -> BS7 4DD | E4: =IF(RAND()>0.8,"Substitute","Account Holder") -> Substitute | F4: =DATE(RANDBETWEEN(2019,2024),RANDBETWEEN(1,12),RANDBETWEEN(1,28)) -> 45628 | G4: =RANDBETWEEN(40,99) -> 59 | H4: =IF(G4>=80,"High", IF(G4>=60,"Medium","Low")) -> Low
A5: ="R-" & (1000 + ROW(A4)) -> R-1004 | B5: ="Rider " & MID(A5,3,4) -> Rider 1004 | C5: =CHOOSE( RANDBETWEEN(1,6), "London", "Manchester", "Birmingham", "Leeds", "Bristol", "Liverpool" ) -> Leeds | D5: =IF(C5="London","E1 " & RANDBETWEEN(1,9) & "AA", IF(C5="Manchester","M" & RANDBETWEEN(1,9) & " 1AA", IF(C5="Birmingham","B" & RANDBETWEEN(1,9) & " 2BB", IF(C5="Leeds","LS" & RANDBETWEEN(1,9) & " 3CC", IF(C5="Bristol","BS" & RANDBETWEEN(1,9) & " 4DD", "L" & RANDBETWEEN(1,9) & " 5EE"))))) -> LS1 3CC | E5: =IF(RAND()>0.8,"Substitute","Account Holder") -> Account Holder | F5: =DATE(RANDBETWEEN(2019,2024),RANDBETWEEN(1,12),RANDBETWEEN(1,28)) -> 45573 | G5: =RANDBETWEEN(40,99) -> 61 | H5: =IF(G5>=80,"High", IF(G5>=60,"Medium","Low")) -> Medium
A6: ="R-" & (1000 + ROW(A5)) -> R-1005 | B6: ="Rider " & MID(A6,3,4) -> Rider 1005 | C6: =CHOOSE( RANDBETWEEN(1,6), "London", "Manchester", "Birmingham", "Leeds", "Bristol", "Liverpool" ) -> Birmingham | D6: =IF(C6="London","E1 " & RANDBETWEEN(1,9) & "AA", IF(C6="Manchester","M" & RANDBETWEEN(1,9) & " 1AA", IF(C6="Birmingham","B" & RANDBETWEEN(1,9) & " 2BB", IF(C6="Leeds","LS" & RANDBETWEEN(1,9) & " 3CC", IF(C6="Bristol","BS" & RANDBETWEEN(1,9) & " 4DD", "L" & RANDBETWEEN(1,9) & " 5EE"))))) -> B1 2BB | E6: =IF(RAND()>0.8,"Substitute","Account Holder") -> Account Holder | F6: =DATE(RANDBETWEEN(2019,2024),RANDBETWEEN(1,12),RANDBETWEEN(1,28)) -> 44794 | G6: =RANDBETWEEN(40,99) -> 70 | H6: =IF(G6>=80,"High", IF(G6>=60,"Medium","Low")) -> Medium
A7: ="R-" & (1000 + ROW(A6)) -> R-1006 | B7: ="Rider " & MID(A7,3,4) -> Rider 1006 | C7: =CHOOSE( RANDBETWEEN(1,6), "London", "Manchester", "Birmingham", "Leeds", "Bristol", "Liverpool" ) -> London | D7: =IF(C7="London","E1 " & RANDBETWEEN(1,9) & "AA", IF(C7="Manchester","M" & RANDBETWEEN(1,9) & " 1AA", IF(C7="Birmingham","B" & RANDBETWEEN(1,9) & " 2BB", IF(C7="Leeds","LS" & RANDBETWEEN(1,9) & " 3CC", IF(C7="Bristol","BS" & RANDBETWEEN(1,9) & " 4DD", "L" & RANDBETWEEN(1,9) & " 5EE"))))) -> E1 3AA | E7: =IF(RAND()>0.8,"Substitute","Account Holder") -> Account Holder | F7: =DATE(RANDBETWEEN(2019,2024),RANDBETWEEN(1,12),RANDBETWEEN(1,28)) -> 43552 | G7: =RANDBETWEEN(40,99) -> 61 | H7: =IF(G7>=80,"High", IF(G7>=60,"Medium","Low")) -> Medium
A8: ="R-" & (1000 + ROW(A7)) -> R-1007 | B8: ="Rider " & MID(A8,3,4) -> Rider 1007 | C8: =CHOOSE( RANDBETWEEN(1,6), "London", "Manchester", "Birmingham", "Leeds", "Bristol", "Liverpool" ) -> Liverpool | D8: =IF(C8="London","E1 " & RANDBETWEEN(1,9) & "AA", IF(C8="Manchester","M" & RANDBETWEEN(1,9) & " 1AA", IF(C8="Birmingham","B" & RANDBETWEEN(1,9) & " 2BB", IF(C8="Leeds","LS" & RANDBETWEEN(1,9) & " 3CC", IF(C8="Bristol","BS" & RANDBETWEEN(1,9) & " 4DD", "L" & RANDBETWEEN(1,9) & " 5EE"))))) -> L4 5EE | E8: =IF(RAND()>0.8,"Substitute","Account Holder") -> Substitute | F8: =DATE(RANDBETWEEN(2019,2024),RANDBETWEEN(1,12),RANDBETWEEN(1,28)) -> 44942 | G8: =RANDBETWEEN(40,99) -> 48 | H8: =IF(G8>=80,"High", IF(G8>=60,"Medium","Low")) -> Low
A9: ="R-" & (1000 + ROW(A8)) -> R-1008 | B9: ="Rider " & MID(A9,3,4) -> Rider 1008 | C9: =CHOOSE( RANDBETWEEN(1,6), "London", "Manchester", "Birmingham", "Leeds", "Bristol", "Liverpool" ) -> Bristol | D9: =IF(C9="London","E1 " & RANDBETWEEN(1,9) & "AA", IF(C9="Manchester","M" & RANDBETWEEN(1,9) & " 1AA", IF(C9="Birmingham","B" & RANDBETWEEN(1,9) & " 2BB", IF(C9="Leeds","LS" & RANDBETWEEN(1,9) & " 3CC", IF(C9="Bristol","BS" & RANDBETWEEN(1,9) & " 4DD", "L" & RANDBETWEEN(1,9) & " 5EE"))))) -> BS4 4DD | E9: =IF(RAND()>0.8,"Substitute","Account Holder") -> Substitute | F9: =DATE(RANDBETWEEN(2019,2024),RANDBETWEEN(1,12),RANDBETWEEN(1,28)) -> 43953 | G9: =RANDBETWEEN(40,99) -> 88 | H9: =IF(G9>=80,"High", IF(G9>=60,"Medium","Low")) -> High
A10: ="R-" & (1000 + ROW(A9)) -> R-1009 | B10: ="Rider " & MID(A10,3,4) -> Rider 1009 | C10: =CHOOSE( RANDBETWEEN(1,6), "London", "Manchester", "Birmingham", "Leeds", "Bristol", "Liverpool" ) -> Birmingham | D10: =IF(C10="London","E1 " & RANDBETWEEN(1,9) & "AA", IF(C10="Manchester","M" & RANDBETWEEN(1,9) & " 1AA", IF(C10="Birmingham","B" & RANDBETWEEN(1,9) & " 2BB", IF(C10="Leeds","LS" & RANDBETWEEN(1,9) & " 3CC", IF(C10="Bristol","BS" & RANDBETWEEN(1,9) & " 4DD", "L" & RANDBETWEEN(1,9) & " 5EE"))))) -> B3 2BB | E10: =IF(RAND()>0.8,"Substitute","Account Holder") -> Account Holder | F10: =DATE(RANDBETWEEN(2019,2024),RANDBETWEEN(1,12),RANDBETWEEN(1,28)) -> 44677 | G10: =RANDBETWEEN(40,99) -> 68 | H10: =IF(G10>=80,"High", IF(G10>=60,"Medium","Low")) -> Medium
A11: ="R-" & (1000 + ROW(A10)) -> R-1010 | B11: ="Rider " & MID(A11,3,4) -> Rider 1010 | C11: =CHOOSE( RANDBETWEEN(1,6), "London", "Manchester", "Birmingham", "Leeds", "Bristol", "Liverpool" ) -> Birmingham | D11: =IF(C11="London","E1 " & RANDBETWEEN(1,9) & "AA", IF(C11="Manchester","M" & RANDBETWEEN(1,9) & " 1AA", IF(C11="Birmingham","B" & RANDBETWEEN(1,9) & " 2BB", IF(C11="Leeds","LS" & RANDBETWEEN(1,9) & " 3CC", IF(C11="Bristol","BS" & RANDBETWEEN(1,9) & " 4DD", "L" & RANDBETWEEN(1,9) & " 5EE"))))) -> B1 2BB | E11: =IF(RAND()>0.8,"Substitute","Account Holder") -> Account Holder | F11: =DATE(RANDBETWEEN(2019,2024),RANDBETWEEN(1,12),RANDBETWEEN(1,28)) -> 45520 | G11: =RANDBETWEEN(40,99) -> 93 | H11: =IF(G11>=80,"High", IF(G11>=60,"Medium","Low")) -> High
A12: ="R-" & (1000 + ROW(A11)) -> R-1011 | B12: ="Rider " & MID(A12,3,4) -> Rider 1011 | C12: =CHOOSE( RANDBETWEEN(1,6), "London", "Manchester", "Birmingham", "Leeds", "Bristol", "Liverpool" ) -> Leeds | D12: =IF(C12="London","E1 " & RANDBETWEEN(1,9) & "AA", IF(C12="Manchester","M" & RANDBETWEEN(1,9) & " 1AA", IF(C12="Birmingham","B" & RANDBETWEEN(1,9) & " 2BB", IF(C12="Leeds","LS" & RANDBETWEEN(1,9) & " 3CC", IF(C12="Bristol","BS" & RANDBETWEEN(1,9) & " 4DD", "L" & RANDBETWEEN(1,9) & " 5EE"))))) -> LS1 3CC | E12: =IF(RAND()>0.8,"Substitute","Account Holder") -> Account Holder | F12: =DATE(RANDBETWEEN(2019,2024),RANDBETWEEN(1,12),RANDBETWEEN(1,28)) -> 45525 | G12: =RANDBETWEEN(40,99) -> 98 | H12: =IF(G12>=80,"High", IF(G12>=60,"Medium","Low")) -> High
A13: ="R-" & (1000 + ROW(A12)) -> R-1012 | B13: ="Rider " & MID(A13,3,4) -> Rider 1012 | C13: =CHOOSE( RANDBETWEEN(1,6), "London", "Manchester", "Birmingham", "Leeds", "Bristol", "Liverpool" ) -> Leeds | D13: =IF(C13="London","E1 " & RANDBETWEEN(1,9) & "AA", IF(C13="Manchester","M" & RANDBETWEEN(1,9) & " 1AA", IF(C13="Birmingham","B" & RANDBETWEEN(1,9) & " 2BB", IF(C13="Leeds","LS" & RANDBETWEEN(1,9) & " 3CC", IF(C13="Bristol","BS" & RANDBETWEEN(1,9) & " 4DD", "L" & RANDBETWEEN(1,9) & " 5EE"))))) -> LS7 3CC | E13: =IF(RAND()>0.8,"Substitute","Account Holder") -> Account Holder | F13: =DATE(RANDBETWEEN(2019,2024),RANDBETWEEN(1,12),RANDBETWEEN(1,28)) -> 43782 | G13: =RANDBETWEEN(40,99) -> 52 | H13: =IF(G13>=80,"High", IF(G13>=60,"Medium","Low")) -> Low
... A5001: ="R-" & (1000 + ROW(A5000)) -> R-6000 | B5001: ="Rider " & MID(A5001,3,4) -> Rider 6000 | C5001: =CHOOSE( RANDBETWEEN(1,6), "London", "Manchester", "Birmingham", "Leeds", "Bristol", "Liverpool" ) -> Manchester | D5001: =IF(C5001="London","E1 " & RANDBETWEEN(1,9) & "AA", IF(C5001="Manchester","M" & RANDBETWEEN(1,9) & " 1AA", IF(C5001="Birmingham","B" & RANDBETWEEN(1,9) & " 2BB", IF(C5001="Leeds","LS" & RANDBETWEEN(1,9) & " 3CC", IF(C5001="Bristol","BS" & RANDBETWEEN(1,9) & " 4DD", "L" & RANDBETWEEN(1,9) & " 5EE"))))) -> M4 1AA | E5001: =IF(RAND()>0.8,"Substitute","Account Holder") -> Substitute | F5001: =DATE(RANDBETWEEN(2019,2024),RANDBETWEEN(1,12),RANDBETWEEN(1,28)) -> 44201 | G5001: =RANDBETWEEN(40,99) -> 79 | H5001: =IF(G5001>=80,"High", IF(G5001>=60,"Medium","Low")) -> Medium

Sheet Fact_Verifications
A1: Verification_ID | B1: Rider_ID | C1: Verification_Date | D1: Verification_Status | E1: Is_Failed | F1: Incident_Feed_Text | G1: Status_Icon
A2: =ROW(A2)-1 -> 1 | B2: ="R-" & (1000 + ROW(A1)) -> R-1001 | C2: =TODAY()-RANDBETWEEN(0,60) -> 46003 | D2: =IF(AND(VLOOKUP(B2,Dim_Riders!A:G,5,FALSE)="Substitute",RAND()>0.7), "Failed - No Match", "Verified - Clear") -> Verified - Clear | E2: =IF(LEFT(D2,6)="Failed",1,0) -> 0 | F2: ="Identity Check: "&B2&" returned status "&D2 -> Identity Check: R-1001 returned status Verified - Clear | G2: =IF(E2=1,"⛔","✅") -> ✅
A3: =ROW(A3)-1 -> 2 | B3: ="R-" & (1000 + ROW(A2)) -> R-1002 | C3: =TODAY()-RANDBETWEEN(0,60) -> 46036 | D3: =IF(AND(VLOOKUP(B3,Dim_Riders!A:G,5,FALSE)="Substitute",RAND()>0.7), "Failed - No Match", "Verified - Clear") -> Verified - Clear | E3: =IF(LEFT(D3,6)="Failed",1,0) -> 0 | F3: ="Identity Check: "&B3&" returned status "&D3 -> Identity Check: R-1002 returned status Verified - Clear | G3: =IF(E3=1,"⛔","✅") -> ✅
A4: =ROW(A4)-1 -> 3 | B4: ="R-" & (1000 + ROW(A3)) -> R-1003 | C4: =TODAY()-RANDBETWEEN(0,60) -> 45997 | D4: =IF(AND(VLOOKUP(B4,Dim_Riders!A:G,5,FALSE)="Substitute",RAND()>0.7), "Failed - No Match", "Verified - Clear") -> Failed - No Match | E4: =IF(LEFT(D4,6)="Failed",1,0) -> 1 | F4: ="Identity Check: "&B4&" returned status "&D4 -> Identity Check: R-1003 returned status Failed - No Match | G4: =IF(E4=1,"⛔","✅") -> ⛔
A5: =ROW(A5)-1 -> 4 | B5: ="R-" & (1000 + ROW(A4)) -> R-1004 | C5: =TODAY()-RANDBETWEEN(0,60) -> 46046 | D5: =IF(AND(VLOOKUP(B5,Dim_Riders!A:G,5,FALSE)="Substitute",RAND()>0.7), "Failed - No Match", "Verified - Clear") -> Verified - Clear | E5: =IF(LEFT(D5,6)="Failed",1,0) -> 0 | F5: ="Identity Check: "&B5&" returned status "&D5 -> Identity Check: R-1004 returned status Verified - Clear | G5: =IF(E5=1,"⛔","✅") -> ✅
A6: =ROW(A6)-1 -> 5 | B6: ="R-" & (1000 + ROW(A5)) -> R-1005 | C6: =TODAY()-RANDBETWEEN(0,60) -> 45994 | D6: =IF(AND(VLOOKUP(B6,Dim_Riders!A:G,5,FALSE)="Substitute",RAND()>0.7), "Failed - No Match", "Verified - Clear") -> Verified - Clear | E6: =IF(LEFT(D6,6)="Failed",1,0) -> 0 | F6: ="Identity Check: "&B6&" returned status "&D6 -> Identity Check: R-1005 returned status Verified - Clear | G6: =IF(E6=1,"⛔","✅") -> ✅
A7: =ROW(A7)-1 -> 6 | B7: ="R-" & (1000 + ROW(A6)) -> R-1006 | C7: =TODAY()-RANDBETWEEN(0,60) -> 46036 | D7: =IF(AND(VLOOKUP(B7,Dim_Riders!A:G,5,FALSE)="Substitute",RAND()>0.7), "Failed - No Match", "Verified - Clear") -> Verified - Clear | E7: =IF(LEFT(D7,6)="Failed",1,0) -> 0 | F7: ="Identity Check: "&B7&" returned status "&D7 -> Identity Check: R-1006 returned status Verified - Clear | G7: =IF(E7=1,"⛔","✅") -> ✅
A8: =ROW(A8)-1 -> 7 | B8: ="R-" & (1000 + ROW(A7)) -> R-1007 | C8: =TODAY()-RANDBETWEEN(0,60) -> 46008 | D8: =IF(AND(VLOOKUP(B8,Dim_Riders!A:G,5,FALSE)="Substitute",RAND()>0.7), "Failed - No Match", "Verified - Clear") -> Verified - Clear | E8: =IF(LEFT(D8,6)="Failed",1,0) -> 0 | F8: ="Identity Check: "&B8&" returned status "&D8 -> Identity Check: R-1007 returned status Verified - Clear | G8: =IF(E8=1,"⛔","✅") -> ✅
A9: =ROW(A9)-1 -> 8 | B9: ="R-" & (1000 + ROW(A8)) -> R-1008 | C9: =TODAY()-RANDBETWEEN(0,60) -> 46006 | D9: =IF(AND(VLOOKUP(B9,Dim_Riders!A:G,5,FALSE)="Substitute",RAND()>0.7), "Failed - No Match", "Verified - Clear") -> Verified - Clear | E9: =IF(LEFT(D9,6)="Failed",1,0) -> 0 | F9: ="Identity Check: "&B9&" returned status "&D9 -> Identity Check: R-1008 returned status Verified - Clear | G9: =IF(E9=1,"⛔","✅") -> ✅
A10: =ROW(A10)-1 -> 9 | B10: ="R-" & (1000 + ROW(A9)) -> R-1009 | C10: =TODAY()-RANDBETWEEN(0,60) -> 46044 | D10: =IF(AND(VLOOKUP(B10,Dim_Riders!A:G,5,FALSE)="Substitute",RAND()>0.7), "Failed - No Match", "Verified - Clear") -> Verified - Clear | E10: =IF(LEFT(D10,6)="Failed",1,0) -> 0 | F10: ="Identity Check: "&B10&" returned status "&D10 -> Identity Check: R-1009 returned status Verified - Clear | G10: =IF(E10=1,"⛔","✅") -> ✅
A11: =ROW(A11)-1 -> 10 | B11: ="R-" & (1000 + ROW(A10)) -> R-1010 | C11: =TODAY()-RANDBETWEEN(0,60) -> 46048 | D11: =IF(AND(VLOOKUP(B11,Dim_Riders!A:G,5,FALSE)="Substitute",RAND()>0.7), "Failed - No Match", "Verified - Clear") -> Verified - Clear | E11: =IF(LEFT(D11,6)="Failed",1,0) -> 0 | F11: ="Identity Check: "&B11&" returned status "&D11 -> Identity Check: R-1010 returned status Verified - Clear | G11: =IF(E11=1,"⛔","✅") -> ✅
A12: =ROW(A12)-1 -> 11 | B12: ="R-" & (1000 + ROW(A11)) -> R-1011 | C12: =TODAY()-RANDBETWEEN(0,60) -> 45996 | D12: =IF(AND(VLOOKUP(B12,Dim_Riders!A:G,5,FALSE)="Substitute",RAND()>0.7), "Failed - No Match", "Verified - Clear") -> Verified - Clear | E12: =IF(LEFT(D12,6)="Failed",1,0) -> 0 | F12: ="Identity Check: "&B12&" returned status "&D12 -> Identity Check: R-1011 returned status Verified - Clear | G12: =IF(E12=1,"⛔","✅") -> ✅
A13: =ROW(A13)-1 -> 12 | B13: ="R-" & (1000 + ROW(A12)) -> R-1012 | C13: =TODAY()-RANDBETWEEN(0,60) -> 46040 | D13: =IF(AND(VLOOKUP(B13,Dim_Riders!A:G,5,FALSE)="Substitute",RAND()>0.7), "Failed - No Match", "Verified - Clear") -> Verified - Clear | E13: =IF(LEFT(D13,6)="Failed",1,0) -> 0 | F13: ="Identity Check: "&B13&" returned status "&D13 -> Identity Check: R-1012 returned status Verified - Clear | G13: =IF(E13=1,"⛔","✅") -> ✅
... A5001: =ROW(A5001)-1 -> 5000 | B5001: ="R-" & (1000 + ROW(A5000)) -> R-6000 | C5001: =TODAY()-RANDBETWEEN(0,60) -> 46017 | D5001: =IF(AND(VLOOKUP(B5001,Dim_Riders!A:G,5,FALSE)="Substitute",RAND()>0.7), "Failed - No Match", "Verified - Clear") -> Verified - Clear | E5001: =IF(LEFT(D5001,6)="Failed",1,0) -> 0 | F5001: ="Identity Check: "&B5001&" returned status "&D5001 -> Identity Check: R-6000 returned status Verified - Clear | G5001: =IF(E5001=1,"⛔","✅") -> ✅

Sheet Fact_Orders
A1: Order_ID | B1: Rider_ID | C1: Order_Date | D1: Order_Value | E1: Is_Phantom_Order | F1: Refund_Amount | G1: Payment_Status | H1: Reason
A2: ="ORD-"&TEXT(ROW(A2)+9999,"00000") -> ORD-10001 | B2: ="R-" & (1000 + ROW(A1)) -> R-1001 | C2: =TODAY()-RANDBETWEEN(0,60) -> 46044 | D2: =RANDBETWEEN(1500,8500)/100 -> 33.75 | E2: 1 | F2: =IF(E2=1, D2, 0) -> 33.75 | G2: =IF(E2=1,"Refunded","Completed") -> Refunded | H2: not delivered
A3: ="ORD-"&TEXT(ROW(A3)+9999,"00000") -> ORD-10002 | B3: ="R-" & (1000 + ROW(A2)) -> R-1002 | C3: =TODAY()-RANDBETWEEN(0,60) -> 46047 | D3: =RANDBETWEEN(1500,8500)/100 -> 64.22 | E3: =IF(VLOOKUP(B3,Dim_Riders!A:H,7,FALSE)="High", IF(RAND()>0.8,1,0), IF(RAND()>0.99,1,0)) -> 0 | F3: =IF(E3=1, D3, 0) -> 0 | G3: =IF(E3=1,"Refunded","Completed") -> Completed | H3: delivered
A4: ="ORD-"&TEXT(ROW(A4)+9999,"00000") -> ORD-10003 | B4: ="R-" & (1000 + ROW(A3)) -> R-1003 | C4: =TODAY()-RANDBETWEEN(0,60) -> 46037 | D4: =RANDBETWEEN(1500,8500)/100 -> 21.07 | E4: =IF(VLOOKUP(B4,Dim_Riders!A:H,7,FALSE)="High", IF(RAND()>0.8,1,0), IF(RAND()>0.99,1,0)) -> 0 | F4: =IF(E4=1, D4, 0) -> 0 | G4: =IF(E4=1,"Refunded","Completed") -> Completed | H4: delivered
A5: ="ORD-"&TEXT(ROW(A5)+9999,"00000") -> ORD-10004 | B5: ="R-" & (1000 + ROW(A4)) -> R-1004 | C5: =TODAY()-RANDBETWEEN(0,60) -> 46010 | D5: =RANDBETWEEN(1500,8500)/100 -> 67.03 | E5: 1 | F5: =IF(E5=1, D5, 0) -> 67.03 | G5: =IF(E5=1,"Refunded","Completed") -> Refunded | H5: delivered
A6: ="ORD-"&TEXT(ROW(A6)+9999,"00000") -> ORD-10005 | B6: ="R-" & (1000 + ROW(A5)) -> R-1005 | C6: =TODAY()-RANDBETWEEN(0,60) -> 46007 | D6: =RANDBETWEEN(1500,8500)/100 -> 34.34 | E6: =IF(VLOOKUP(B6,Dim_Riders!A:H,7,FALSE)="High", IF(RAND()>0.8,1,0), IF(RAND()>0.99,1,0)) -> 0 | F6: =IF(E6=1, D6, 0) -> 0 | G6: =IF(E6=1,"Refunded","Completed") -> Completed | H6: delivered
A7: ="ORD-"&TEXT(ROW(A7)+9999,"00000") -> ORD-10006 | B7: ="R-" & (1000 + ROW(A6)) -> R-1006 | C7: =TODAY()-RANDBETWEEN(0,60) -> 46016 | D7: =RANDBETWEEN(1500,8500)/100 -> 73.77 | E7: =IF(VLOOKUP(B7,Dim_Riders!A:H,7,FALSE)="High", IF(RAND()>0.8,1,0), IF(RAND()>0.99,1,0)) -> 0 | F7: =IF(E7=1, D7, 0) -> 0 | G7: =IF(E7=1,"Refunded","Completed") -> Completed | H7: delivered
A8: ="ORD-"&TEXT(ROW(A8)+9999,"00000") -> ORD-10007 | B8: ="R-" & (1000 + ROW(A7)) -> R-1007 | C8: =TODAY()-RANDBETWEEN(0,60) -> 46003 | D8: =RANDBETWEEN(1500,8500)/100 -> 75.1 | E8: 1 | F8: =IF(E8=1, D8, 0) -> 75.1 | G8: =IF(E8=1,"Refunded","Completed") -> Refunded | H8: not delivered
A9: ="ORD-"&TEXT(ROW(A9)+9999,"00000") -> ORD-10008 | B9: ="R-" & (1000 + ROW(A8)) -> R-1008 | C9: =TODAY()-RANDBETWEEN(0,60) -> 46013 | D9: =RANDBETWEEN(1500,8500)/100 -> 23.7 | E9: =IF(VLOOKUP(B9,Dim_Riders!A:H,7,FALSE)="High", IF(RAND()>0.8,1,0), IF(RAND()>0.99,1,0)) -> 0 | F9: =IF(E9=1, D9, 0) -> 0 | G9: =IF(E9=1,"Refunded","Completed") -> Completed | H9: delivered
A10: ="ORD-"&TEXT(ROW(A10)+9999,"00000") -> ORD-10009 | B10: ="R-" & (1000 + ROW(A9)) -> R-1009 | C10: =TODAY()-RANDBETWEEN(0,60) -> 46032 | D10: =RANDBETWEEN(1500,8500)/100 -> 34.33 | E10: =IF(VLOOKUP(B10,Dim_Riders!A:H,7,FALSE)="High", IF(RAND()>0.8,1,0), IF(RAND()>0.99,1,0)) -> 0 | F10: =IF(E10=1, D10, 0) -> 0 | G10: =IF(E10=1,"Refunded","Completed") -> Completed | H10: delivered
A11: ="ORD-"&TEXT(ROW(A11)+9999,"00000") -> ORD-10010 | B11: ="R-" & (1000 + ROW(A10)) -> R-1010 | C11: =TODAY()-RANDBETWEEN(0,60) -> 46026 | D11: =RANDBETWEEN(1500,8500)/100 -> 74.71 | E11: =IF(VLOOKUP(B11,Dim_Riders!A:H,7,FALSE)="High", IF(RAND()>0.8,1,0), IF(RAND()>0.99,1,0)) -> 0 | F11: =IF(E11=1, D11, 0) -> 0 | G11: =IF(E11=1,"Refunded","Completed") -> Completed | H11: delivered
A12: ="ORD-"&TEXT(ROW(A12)+9999,"00000") -> ORD-10011 | B12: ="R-" & (1000 + ROW(A11)) -> R-1011 | C12: =TODAY()-RANDBETWEEN(0,60) -> 46026 | D12: =RANDBETWEEN(1500,8500)/100 -> 24.37 | E12: =IF(VLOOKUP(B12,Dim_Riders!A:H,7,FALSE)="High", IF(RAND()>0.8,1,0), IF(RAND()>0.99,1,0)) -> 0 | F12: =IF(E12=1, D12, 0) -> 0 | G12: =IF(E12=1,"Refunded","Completed") -> Completed | H12: delivered
A13: ="ORD-"&TEXT(ROW(A13)+9999,"00000") -> ORD-10012 | B13: ="R-" & (1000 + ROW(A12)) -> R-1012 | C13: =TODAY()-RANDBETWEEN(0,60) -> 46022 | D13: =RANDBETWEEN(1500,8500)/100 -> 37.76 | E13: =IF(VLOOKUP(B13,Dim_Riders!A:H,7,FALSE)="High", IF(RAND()>0.8,1,0), IF(RAND()>0.99,1,0)) -> 0 | F13: =IF(E13=1, D13, 0) -> 0 | G13: =IF(E13=1,"Refunded","Completed") -> Completed | H13: delivered
A14: ="ORD-"&TEXT(ROW(A14)+9999,"00000") -> ORD-10013 | B14: ="R-" & (1000 + ROW(A13)) -> R-1013 | C14: =TODAY()-RANDBETWEEN(0,60) -> 46017 | D14: =RANDBETWEEN(1500,8500)/100 -> 84.32 | E14: 1 | F14: =IF(E14=1, D14, 0) -> 84.32 | G14: =IF(E14=1,"Refunded","Completed") -> Refunded | H14: not delivered
A15: ="ORD-"&TEXT(ROW(A15)+9999,"00000") -> ORD-10014 | B15: ="R-" & (1000 + ROW(A14)) -> R-1014 | C15: =TODAY()-RANDBETWEEN(0,60) -> 46016 | D15: =RANDBETWEEN(1500,8500)/100 -> 26.89 | E15: 1 | F15: =IF(E15=1, D15, 0) -> 26.89 | G15: =IF(E15=1,"Refunded","Completed") -> Refunded | H15: tempered
A16: ="ORD-"&TEXT(ROW(A16)+9999,"00000") -> ORD-10015 | B16: ="R-" & (1000 + ROW(A15)) -> R-1015 | C16: =TODAY()-RANDBETWEEN(0,60) -> 46040 | D16: =RANDBETWEEN(1500,8500)/100 -> 64.69 | E16: 1 | F16: =IF(E16=1, D16, 0) -> 64.69 | G16: =IF(E16=1,"Refunded","Completed") -> Refunded | H16: tempered
A17: ="ORD-"&TEXT(ROW(A17)+9999,"00000") -> ORD-10016 | B17: ="R-" & (1000 + ROW(A16)) -> R-1016 | C17: =TODAY()-RANDBETWEEN(0,60) -> 46000 | D17: =RANDBETWEEN(1500,8500)/100 -> 76.03 | E17: 0 | F17: =IF(E17=1, D17, 0) -> 0 | G17: =IF(E17=1,"Refunded","Completed") -> Completed | H17: delivered
A18: ="ORD-"&TEXT(ROW(A18)+9999,"00000") -> ORD-10017 | B18: ="R-" & (1000 + ROW(A17)) -> R-1017 | C18: =TODAY()-RANDBETWEEN(0,60) -> 46026 | D18: =RANDBETWEEN(1500,8500)/100 -> 71.6 | E18: 0 | F18: =IF(E18=1, D18, 0) -> 0 | G18: =IF(E18=1,"Refunded","Completed") -> Completed | H18: delivered
A19: ="ORD-"&TEXT(ROW(A19)+9999,"00000") -> ORD-10018 | B19: ="R-" & (1000 + ROW(A18)) -> R-1018 | C19: =TODAY()-RANDBETWEEN(0,60) -> 45991 | D19: =RANDBETWEEN(1500,8500)/100 -> 80.6 | E19: =IF(VLOOKUP(B19,Dim_Riders!A:H,7,FALSE)="High", IF(RAND()>0.8,1,0), IF(RAND()>0.99,1,0)) -> 0 | F19: =IF(E19=1, D19, 0) -> 0 | G19: =IF(E19=1,"Refunded","Completed") -> Completed | H19: delivered
A20: ="ORD-"&TEXT(ROW(A20)+9999,"00000") -> ORD-10019 | B20: ="R-" & (1000 + ROW(A19)) -> R-1019 | C20: =TODAY()-RANDBETWEEN(0,60) -> 45996 | D20: =RANDBETWEEN(1500,8500)/100 -> 77.87 | E20: =IF(VLOOKUP(B20,Dim_Riders!A:H,7,FALSE)="High", IF(RAND()>0.8,1,0), IF(RAND()>0.99,1,0)) -> 0 | F20: =IF(E20=1, D20, 0) -> 0 | G20: =IF(E20=1,"Refunded","Completed") -> Completed | H20: delivered
A21: ="ORD-"&TEXT(ROW(A21)+9999,"00000") -> ORD-10020 | B21: ="R-" & (1000 + ROW(A20)) -> R-1020 | C21: =TODAY()-RANDBETWEEN(0,60) -> 45996 | D21: =RANDBETWEEN(1500,8500)/100 -> 43.8 | E21: =IF(VLOOKUP(B21,Dim_Riders!A:H,7,FALSE)="High", IF(RAND()>0.8,1,0), IF(RAND()>0.99,1,0)) -> 0 | F21: =IF(E21=1, D21, 0) -> 0 | G21: =IF(E21=1,"Refunded","Completed") -> Completed | H21: delivered
A22: ="ORD-"&TEXT(ROW(A22)+9999,"00000") -> ORD-10021 | B22: ="R-" & (1000 + ROW(A21)) -> R-1021 | C22: =TODAY()-RANDBETWEEN(0,60) -> 46020 | D22: =RANDBETWEEN(1500,8500)/100 -> 48.53 | E22: =IF(VLOOKUP(B22,Dim_Riders!A:H,7,FALSE)="High", IF(RAND()>0.8,1,0), IF(RAND()>0.99,1,0)) -> 0 | F22: =IF(E22=1, D22, 0) -> 0 | G22: =IF(E22=1,"Refunded","Completed") -> Completed | H22: delivered
A23: ="ORD-"&TEXT(ROW(A23)+9999,"00000") -> ORD-10022 | B23: ="R-" & (1000 + ROW(A22)) -> R-1022 | C23: =TODAY()-RANDBETWEEN(0,60) -> 46025 | D23: =RANDBETWEEN(1500,8500)/100 -> 22.92 | E23: =IF(VLOOKUP(B23,Dim_Riders!A:H,7,FALSE)="High", IF(RAND()>0.8,1,0), IF(RAND()>0.99,1,0)) -> 0 | F23: =IF(E23=1, D23, 0) -> 0 | G23: =IF(E23=1,"Refunded","Completed") -> Completed | H23: delivered
A24: ="ORD-"&TEXT(ROW(A24)+9999,"00000") -> ORD-10023 | B24: ="R-" & (1000 + ROW(A23)) -> R-1023 | C24: =TODAY()-RANDBETWEEN(0,60) -> 46037 | D24: =RANDBETWEEN(1500,8500)/100 -> 74.99 | E24: 1 | F24: =IF(E24=1, D24, 0) -> 74.99 | G24: =IF(E24=1,"Refunded","Completed") -> Refunded | H24: not delivered
A25: ="ORD-"&TEXT(ROW(A25)+9999,"00000") -> ORD-10024 | B25: ="R-" & (1000 + ROW(A24)) -> R-1024 | C25: =TODAY()-RANDBETWEEN(0,60) -> 46015 | D25: =RANDBETWEEN(1500,8500)/100 -> 73.4 | E25: =IF(VLOOKUP(B25,Dim_Riders!A:H,7,FALSE)="High", IF(RAND()>0.8,1,0), IF(RAND()>0.99,1,0)) -> 0 | F25: =IF(E25=1, D25, 0) -> 0 | G25: =IF(E25=1,"Refunded","Completed") -> Completed | H25: delivered
A26: ="ORD-"&TEXT(ROW(A26)+9999,"00000") -> ORD-10025 | B26: ="R-" & (1000 + ROW(A25)) -> R-1025 | C26: =TODAY()-RANDBETWEEN(0,60) -> 46039 | D26: =RANDBETWEEN(1500,8500)/100 -> 77.3 | E26: =IF(VLOOKUP(B26,Dim_Riders!A:H,7,FALSE)="High", IF(RAND()>0.8,1,0), IF(RAND()>0.99,1,0)) -> 0 | F26: =IF(E26=1, D26, 0) -> 0 | G26: =IF(E26=1,"Refunded","Completed") -> Completed | H26: delivered
A27: ="ORD-"&TEXT(ROW(A27)+9999,"00000") -> ORD-10026 | B27: ="R-" & (1000 + ROW(A26)) -> R-1026 | C27: =TODAY()-RANDBETWEEN(0,60) -> 46005 | D27: =RANDBETWEEN(1500,8500)/100 -> 69.61 | E27: 1 | F27: =IF(E27=1, D27, 0) -> 69.61 | G27: =IF(E27=1,"Refunded","Completed") -> Refunded | H27: delivered
A28: ="ORD-"&TEXT(ROW(A28)+9999,"00000") -> ORD-10027 | B28: ="R-" & (1000 + ROW(A27)) -> R-1027 | C28: =TODAY()-RANDBETWEEN(0,60) -> 46037 | D28: =RANDBETWEEN(1500,8500)/100 -> 65.68 | E28: =IF(VLOOKUP(B28,Dim_Riders!A:H,7,FALSE)="High", IF(RAND()>0.8,1,0), IF(RAND()>0.99,1,0)) -> 0 | F28: =IF(E28=1, D28, 0) -> 0 | G28: =IF(E28=1,"Refunded","Completed") -> Completed | H28: delivered
A29: ="ORD-"&TEXT(ROW(A29)+9999,"00000") -> ORD-10028 | B29: ="R-" & (1000 + ROW(A28)) -> R-1028 | C29: =TODAY()-RANDBETWEEN(0,60) -> 46049 | D29: =RANDBETWEEN(1500,8500)/100 -> 52.46 | E29: =IF(VLOOKUP(B29,Dim_Riders!A:H,7,FALSE)="High", IF(RAND()>0.8,1,0), IF(RAND()>0.99,1,0)) -> 0 | F29: =IF(E29=1, D29, 0) -> 0 | G29: =IF(E29=1,"Refunded","Completed") -> Completed | H29: delivered
A30: ="ORD-"&TEXT(ROW(A30)+9999,"00000") -> ORD-10029 | B30: ="R-" & (1000 + ROW(A29)) -> R-1029 | C30: =TODAY()-RANDBETWEEN(0,60) -> 45992 | D30: =RANDBETWEEN(1500,8500)/100 -> 18.36 | E30: =IF(VLOOKUP(B30,Dim_Riders!A:H,7,FALSE)="High", IF(RAND()>0.8,1,0), IF(RAND()>0.99,1,0)) -> 0 | F30: =IF(E30=1, D30, 0) -> 0 | G30: =IF(E30=1,"Refunded","Completed") -> Completed | H30: delivered
A31: ="ORD-"&TEXT(ROW(A31)+9999,"00000") -> ORD-10030 | B31: ="R-" & (1000 + ROW(A30)) -> R-1030 | C31: =TODAY()-RANDBETWEEN(0,60) -> 46022 | D31: =RANDBETWEEN(1500,8500)/100 -> 31.17 | E31: =IF(VLOOKUP(B31,Dim_Riders!A:H,7,FALSE)="High", IF(RAND()>0.8,1,0), IF(RAND()>0.99,1,0)) -> 0 | F31: =IF(E31=1, D31, 0) -> 0 | G31: =IF(E31=1,"Refunded","Completed") -> Completed | H31: delivered
A32: ="ORD-"&TEXT(ROW(A32)+9999,"00000") -> ORD-10031 | B32: ="R-" & (1000 + ROW(A31)) -> R-1031 | C32: =TODAY()-RANDBETWEEN(0,60) -> 45991 | D32: =RANDBETWEEN(1500,8500)/100 -> 38.06 | E32: =IF(VLOOKUP(B32,Dim_Riders!A:H,7,FALSE)="High", IF(RAND()>0.8,1,0), IF(RAND()>0.99,1,0)) -> 0 | F32: =IF(E32=1, D32, 0) -> 0 | G32: =IF(E32=1,"Refunded","Completed") -> Completed | H32: delivered
A33: ="ORD-"&TEXT(ROW(A33)+9999,"00000") -> ORD-10032 | B33: ="R-" & (1000 + ROW(A32)) -> R-1032 | C33: =TODAY()-RANDBETWEEN(0,60) -> 46044 | D33: =RANDBETWEEN(1500,8500)/100 -> 15.18 | E33: 1 | F33: =IF(E33=1, D33, 0) -> 15.18 | G33: =IF(E33=1,"Refunded","Completed") -> Refunded | H33: delivered
A34: ="ORD-"&TEXT(ROW(A34)+9999,"00000") -> ORD-10033 | B34: ="R-" & (1000 + ROW(A33)) -> R-1033 | C34: =TODAY()-RANDBETWEEN(0,60) -> 46049 | D34: =RANDBETWEEN(1500,8500)/100 -> 67.57 | E34: =IF(VLOOKUP(B34,Dim_Riders!A:H,7,FALSE)="High", IF(RAND()>0.8,1,0), IF(RAND()>0.99,1,0)) -> 0 | F34: =IF(E34=1, D34, 0) -> 0 | G34: =IF(E34=1,"Refunded","Completed") -> Completed | H34: delivered
A35: ="ORD-"&TEXT(ROW(A35)+9999,"00000") -> ORD-10034 | B35: ="R-" & (1000 + ROW(A34)) -> R-1034 | C35: =TODAY()-RANDBETWEEN(0,60) -> 45999 | D35: =RANDBETWEEN(1500,8500)/100 -> 84.72 | E35: =IF(VLOOKUP(B35,Dim_Riders!A:H,7,FALSE)="High", IF(RAND()>0.8,1,0), IF(RAND()>0.99,1,0)) -> 0 | F35: =IF(E35=1, D35, 0) -> 0 | G35: =IF(E35=1,"Refunded","Completed") -> Completed | H35: delivered
A36: ="ORD-"&TEXT(ROW(A36)+9999,"00000") -> ORD-10035 | B36: ="R-" & (1000 + ROW(A35)) -> R-1035 | C36: =TODAY()-RANDBETWEEN(0,60) -> 45994 | D36: =RANDBETWEEN(1500,8500)/100 -> 37.35 | E36: =IF(VLOOKUP(B36,Dim_Riders!A:H,7,FALSE)="High", IF(RAND()>0.8,1,0), IF(RAND()>0.99,1,0)) -> 1 | F36: =IF(E36=1, D36, 0) -> 37.35 | G36: =IF(E36=1,"Refunded","Completed") -> Refunded | H36: delivered
A37: ="ORD-"&TEXT(ROW(A37)+9999,"00000") -> ORD-10036 | B37: ="R-" & (1000 + ROW(A36)) -> R-1036 | C37: =TODAY()-RANDBETWEEN(0,60) -> 46034 | D37: =RANDBETWEEN(1500,8500)/100 -> 40.43 | E37: 1 | F37: =IF(E37=1, D37, 0) -> 40.43 | G37: =IF(E37=1,"Refunded","Completed") -> Refunded | H37: delivered
A38: ="ORD-"&TEXT(ROW(A38)+9999,"00000") -> ORD-10037 | B38: ="R-" & (1000 + ROW(A37)) -> R-1037 | C38: =TODAY()-RANDBETWEEN(0,60) -> 46032 | D38: =RANDBETWEEN(1500,8500)/100 -> 83.41 | E38: =IF(VLOOKUP(B38,Dim_Riders!A:H,7,FALSE)="High", IF(RAND()>0.8,1,0), IF(RAND()>0.99,1,0)) -> 0 | F38: =IF(E38=1, D38, 0) -> 0 | G38: =IF(E38=1,"Refunded","Completed") -> Completed | H38: delivered
A39: ="ORD-"&TEXT(ROW(A39)+9999,"00000") -> ORD-10038 | B39: ="R-" & (1000 + ROW(A38)) -> R-1038 | C39: =TODAY()-RANDBETWEEN(0,60) -> 46025 | D39: =RANDBETWEEN(1500,8500)/100 -> 71.98 | E39: =IF(VLOOKUP(B39,Dim_Riders!A:H,7,FALSE)="High", IF(RAND()>0.8,1,0), IF(RAND()>0.99,1,0)) -> 0 | F39: =IF(E39=1, D39, 0) -> 0 | G39: =IF(E39=1,"Refunded","Completed") -> Completed | H39: delivered
A40: ="ORD-"&TEXT(ROW(A40)+9999,"00000") -> ORD-10039 | B40: ="R-" & (1000 + ROW(A39)) -> R-1039 | C40: =TODAY()-RANDBETWEEN(0,60) -> 46009 | D40: =RANDBETWEEN(1500,8500)/100 -> 32.93 | E40: 1 | F40: =IF(E40=1, D40, 0) -> 32.93 | G40: =IF(E40=1,"Refunded","Completed") -> Refunded | H40: delivered
...
